Workbook

Sheet References
A1: 0 | B1: <= | C1: INSUFICIENTE | D1: < | E1: 0.5 | H1: Dates
A2: 0.5 | B2: <= | C2: MEDIANO | D2: < | E2: 0.8 | H2: 44927
A3: 0.8 | B3: <= | C3: SATISFATÓRIO | D3: < | E3: 0.95 | H3: 44958
A4: 0.95 | B4: <= | C4: EXCELENTE | D4: <= | E4: 1 | H4: 44986
H5: 45017
H6: 45047
H7: 45078
H8: 45108
H9: 45139
H10: 45170
H11: 45200
H12: 45231
H13: 45261
H14: 45292
H15: 45323
H16: 45352
... H37: 45992

Sheet HSE Checklist
A1: CHECK-LIST DE IMPLEMENTAÇÃO HSE EM OBRA | I1: =IF(COUNTA(D11:F126)=(COUNTA(A10:A126)-8),"FORMULÁRIO COMPLETO","FORMULÁRIO INCOMPLETO") -> FORMULÁRIO COMPLETO | K1: Passo a passo:
A2: VAMED Engineering | K2: 1 - Limpe o formulário clicando no botão "LIMPAR FORMULÁRIO". 2 - Preencha todos os campos C, NC e NA conforme indicado na legenda. 3 - Se o indicador estiver verde e escrito "FORMULÁRIO COMPLETO", clique em "GRAVAR NOTA". 4 - Se o indicador estiver vermelho e escrito "FORMULÁRIO INCOMPLETO", cheque se todos os campos C, NC e NA foram preenchidos; 5 - Após confirmação de "Formulário Completo" imprima e recolha as assinaturas necessárias.
A3: PRO-fit
A4: Nome da obra: | C4: Hospital Militar Regional Do Huambo | D4: Centro de custo: | G4: 13DC – DEI/SV/2021
A5: Site manager: | C5: Eduardo Silva | D5: Mês: | G5: 45017
A6: Téc. de Segurança e Amb.: | C6: Faustino dos Santos
A8: ID | B8: Itens a verificar | D8: C | E8: NC | F8: NA | G8: Observações
A9: C: CONFORME, NC: NÃO CONFORME, NA: NÃO SE APLICA | K9: Última nota gravada: | M9: =IF(SUM(HSE_checklist_database[Date])=0,"",MAX(HSE_checklist_database[Date]))
A10: 1 | B10: Documentação / Procedimentos de obra
A11: 1.1 | B11: Manual HSE VAMED actualizado | D11: X | H11: =IF(AND(E11="X",G11=""),"<<< Escreva uma justificativa para esta Não Conformidade!","")
A12: 1.2 | B12: Licença de Obra (afixada) | D12: X | H12: =IF(AND(E12="X",G12=""),"<<< Escreva uma justificativa para esta Não Conformidade!","")
A13: 1.3 | B13: Plano de Segurança e Saúde aprovado | D13: X | H13: =IF(AND(E13="X",G13=""),"<<< Escreva uma justificativa para esta Não Conformidade!","")
A14: 1.4 | B14: Plano de Gestão Ambiental aprovado | D14: X | H14: =IF(AND(E14="X",G14=""),"<<< Escreva uma justificativa para esta Não Conformidade!","")
A15: 1.5 | B15: Plano de Gestão de Resíduos aprovado pela ANR | D15: X | H15: =IF(AND(E15="X",G15=""),"<<< Escreva uma justificativa para esta Não Conformidade!","")
A16: 1.6 | B16: Licença dos geradores | D16: X | H16: =IF(AND(E16="X",G16=""),"<<< Escreva uma justificativa para esta Não Conformidade!","")
A17: 1.7 | B17: Certificado dos Bombeiros | D17: X | H17: =IF(AND(E17="X",G17=""),"<<< Escreva uma justificativa para esta Não Conformidade!","")
A18: 1.8 | B18: Procedimentos de Segurança submetidos e aprovados para as actividades em curso | D18: X | H18: =IF(AND(E18="X",G18=""),"<<< Escreva uma justificativa para esta Não Conformidade!","")
A19: 1.9 | B19: Documentação dos trabalhadores (Documento de identificação, atestado médico, Entrega EPI, Certificado Aptidão) | D19: X | H19: =IF(AND(E19="X",G19=""),"<<< Escreva uma justificativa para esta Não Conformidade!","")
A20: 1.10 | B20: Documentação das empresas (Alvará, Seguro AT, Contribuinte e Seg. Social) | D20: X | H20: =IF(AND(E20="X",G20=""),"<<< Escreva uma justificativa para esta Não Conformidade!","")
A21: 1.11 | B21: Documentação dos equipamentos | D21: X | H21: =IF(AND(E21="X",G21=""),"<<< Escreva uma justificativa para esta Não Conformidade!","")
A22: 1.12 | B22: Indução com atribuição de autocolante | D22: X | H22: =IF(AND(E22="X",G22=""),"<<< Escreva uma justificativa para esta Não Conformidade!","")
A23: 1.13 | B23: Reunião semanal HSE implementada | D23: X | H23: =IF(AND(E23="X",G23=""),"<<< Escreva uma justificativa para esta Não Conformidade!","")
A24: 1.14 | B24: Relatório mensal implementado | D24: X | H24: =IF(AND(E24="X",G24=""),"<<< Escreva uma justificativa para esta Não Conformidade!","")
A25: 1.15 | B25: Quadro de sinistralidade | D25: X | H25: =IF(AND(E25="X",G25=""),"<<< Escreva uma justificativa para esta Não Conformidade!","")
A26: 1.16 | B26: Investigação de acidentes | F26: X | G26: Nãso se verificaram ocorrências no presente mês. | H26: =IF(AND(E26="X",G26=""),"<<< Escreva uma justificativa para esta Não Conformidade!","")
A27: 1.17 | B27: Relatório trimestral (INGA) | D27: X | H27: =IF(AND(E27="X",G27=""),"<<< Escreva uma justificativa para esta Não Conformidade!","")
A28: 1.18 | B28: Relatório semestral (Entidades financiadoras) | D28: X | H28: =IF(AND(E28="X",G28=""),"<<< Escreva uma justificativa para esta Não Conformidade!","")
A29: 1.19 | B29: N.º Técnicos de Segurança dos subcontratados de acordo com as regras VAMED | D29: X | H29: =IF(AND(E29="X",G29=""),"<<< Escreva uma justificativa para esta Não Conformidade!","")
A30: 1.20 | B30: Sensibilização semanal de HSE | D30: X | H30: =IF(AND(E30="X",G30=""),"<<< Escreva uma justificativa para esta Não Conformidade!","")
A31: 1.21 | B31: Realização de controlos de alcoolemia | D31: X | H31: =IF(AND(E31="X",G31=""),"<<< Escreva uma justificativa para esta Não Conformidade!","")
A32: 1.22 | B32: Licença de origem das matérias primas | D32: X
A33: 1.23 | B33: Realização de indução aos visitantes | D33: X
A34: 1.24 | B34: Formação mensal aos seguranças | D34: X
A35: 1.25 | B35: Recolha da documentação dos seguranças | D35: X
A36: 1.26 | B36: Cumprimento do SEP (Stakeholders Engagement Plan) | D36: X
A37: 1.27 | B37: Interação mensal com as comunidades | D37: X
A38: 1.28 | B38: Implementação do projeto de responsabilidade social | D38: X | G38: A acção será retomada no início de 2026.
A39: 1.29 | B39: Inspeção e condições de habitabilidade das bases de vida dos subcontratados | D39: X
A40: 1.30 | B40: Criação da CPAT ou definição do representante dos trabalhadores | D40: X
A41: 1.31 | B41: Reconhecimento mensal | D41: X
...

Sheet Calc
A1: ID | B1: ITENS A VERIFICAR | C1: Peso Ponderado (1 a 3) | E1: PESO RELATIVO TOTAL Σ100% | F1: PESO RELATIVO CALC Σ100% | G1: ='HSE Checklist'!G5 -> 45017
A2: 1_1 | B2: ='HSE Checklist'!B11 -> Manual HSE VAMED actualizado | C2: 2 | D2: =IF('HSE Checklist'!F11<>"",'HSE Checklist'!F11,"") | E2: =1/COUNTA($A$2:$A$110) -> 0.0091743119 | F2: =IF(D2="X",0,1/(COUNTA($A$2:$A$110)-COUNTIF($D$2:$D$110,"X"))) -> 0.0095238095 | G2: =IF(D2="X",F2,IF('HSE Checklist'!D11="X",F2,-F2)) -> 0.0095238095
A3: 1_2 | B3: ='HSE Checklist'!B12 -> Licença de Obra (afixada) | C3: 1 | D3: =IF('HSE Checklist'!F12<>"",'HSE Checklist'!F12,"") | E3: =1/COUNTA($A$2:$A$110) -> 0.0091743119 | F3: =IF(D3="X",0,1/(COUNTA($A$2:$A$110)-COUNTIF($D$2:$D$110,"X"))) -> 0.0095238095 | G3: =IF(D3="X",F3,IF('HSE Checklist'!D12="X",F3,-F3)) -> 0.0095238095
A4: 1_3 | B4: ='HSE Checklist'!B13 -> Plano de Segurança e Saúde aprovado | C4: 3 | D4: =IF('HSE Checklist'!F13<>"",'HSE Checklist'!F13,"") | E4: =1/COUNTA($A$2:$A$110) -> 0.0091743119 | F4: =IF(D4="X",0,1/(COUNTA($A$2:$A$110)-COUNTIF($D$2:$D$110,"X"))) -> 0.0095238095 | G4: =IF(D4="X",F4,IF('HSE Checklist'!D13="X",F4,-F4)) -> 0.0095238095
A5: 1_4 | B5: ='HSE Checklist'!B14 -> Plano de Gestão Ambiental aprovado | C5: 3 | D5: =IF('HSE Checklist'!F14<>"",'HSE Checklist'!F14,"") | E5: =1/COUNTA($A$2:$A$110) -> 0.0091743119 | F5: =IF(D5="X",0,1/(COUNTA($A$2:$A$110)-COUNTIF($D$2:$D$110,"X"))) -> 0.0095238095 | G5: =IF(D5="X",F5,IF('HSE Checklist'!D14="X",F5,-F5)) -> 0.0095238095
A6: 1_5 | B6: ='HSE Checklist'!B15 -> Plano de Gestão de Resíduos aprovado pela ANR | C6: 1 | D6: =IF('HSE Checklist'!F15<>"",'HSE Checklist'!F15,"") | E6: =1/COUNTA($A$2:$A$110) -> 0.0091743119 | F6: =IF(D6="X",0,1/(COUNTA($A$2:$A$110)-COUNTIF($D$2:$D$110,"X"))) -> 0.0095238095 | G6: =IF(D6="X",F6,IF('HSE Checklist'!D15="X",F6,-F6)) -> 0.0095238095
A7: 1_6 | B7: ='HSE Checklist'!B16 -> Licença dos geradores | C7: 3 | D7: =IF('HSE Checklist'!F16<>"",'HSE Checklist'!F16,"") | E7: =1/COUNTA($A$2:$A$110) -> 0.0091743119 | F7: =IF(D7="X",0,1/(COUNTA($A$2:$A$110)-COUNTIF($D$2:$D$110,"X"))) -> 0.0095238095 | G7: =IF(D7="X",F7,IF('HSE Checklist'!D16="X",F7,-F7)) -> 0.0095238095
A8: 1_7 | B8: ='HSE Checklist'!B17 -> Certificado dos Bombeiros | C8: 3 | D8: =IF('HSE Checklist'!F17<>"",'HSE Checklist'!F17,"") | E8: =1/COUNTA($A$2:$A$110) -> 0.0091743119 | F8: =IF(D8="X",0,1/(COUNTA($A$2:$A$110)-COUNTIF($D$2:$D$110,"X"))) -> 0.0095238095 | G8: =IF(D8="X",F8,IF('HSE Checklist'!D17="X",F8,-F8)) -> 0.0095238095
A9: 1_8 | B9: ='HSE Checklist'!B18 -> Procedimentos de Segurança submetidos e aprovados para as actividades em curso | C9: 3 | D9: =IF('HSE Checklist'!F18<>"",'HSE Checklist'!F18,"") | E9: =1/COUNTA($A$2:$A$110) -> 0.0091743119 | F9: =IF(D9="X",0,1/(COUNTA($A$2:$A$110)-COUNTIF($D$2:$D$110,"X"))) -> 0.0095238095 | G9: =IF(D9="X",F9,IF('HSE Checklist'!D18="X",F9,-F9)) -> 0.0095238095
A10: 1_9 | B10: ='HSE Checklist'!B19 -> Documentação dos trabalhadores (Documento de identificação, atestado médico, Entrega EPI, Certificado Aptidão) | C10: 3 | D10: =IF('HSE Checklist'!F19<>"",'HSE Checklist'!F19,"") | E10: =1/COUNTA($A$2:$A$110) -> 0.0091743119 | F10: =IF(D10="X",0,1/(COUNTA($A$2:$A$110)-COUNTIF($D$2:$D$110,"X"))) -> 0.0095238095 | G10: =IF(D10="X",F10,IF('HSE Checklist'!D19="X",F10,-F10)) -> 0.0095238095
A11: 1_10 | B11: ='HSE Checklist'!B20 -> Documentação das empresas (Alvará, Seguro AT, Contribuinte e Seg. Social) | C11: 3 | D11: =IF('HSE Checklist'!F20<>"",'HSE Checklist'!F20,"") | E11: =1/COUNTA($A$2:$A$110) -> 0.0091743119 | F11: =IF(D11="X",0,1/(COUNTA($A$2:$A$110)-COUNTIF($D$2:$D$110,"X"))) -> 0.0095238095 | G11: =IF(D11="X",F11,IF('HSE Checklist'!D20="X",F11,-F11)) -> 0.0095238095
A12: 1_11 | B12: ='HSE Checklist'!B21 -> Documentação dos equipamentos | C12: 3 | D12: =IF('HSE Checklist'!F21<>"",'HSE Checklist'!F21,"") | E12: =1/COUNTA($A$2:$A$110) -> 0.0091743119 | F12: =IF(D12="X",0,1/(COUNTA($A$2:$A$110)-COUNTIF($D$2:$D$110,"X"))) -> 0.0095238095 | G12: =IF(D12="X",F12,IF('HSE Checklist'!D21="X",F12,-F12)) -> 0.0095238095
A13: 1_12 | B13: ='HSE Checklist'!B22 -> Indução com atribuição de autocolante | C13: 2 | D13: =IF('HSE Checklist'!F22<>"",'HSE Checklist'!F22,"") | E13: =1/COUNTA($A$2:$A$110) -> 0.0091743119 | F13: =IF(D13="X",0,1/(COUNTA($A$2:$A$110)-COUNTIF($D$2:$D$110,"X"))) -> 0.0095238095 | G13: =IF(D13="X",F13,IF('HSE Checklist'!D22="X",F13,-F13)) -> 0.0095238095
... A33: 1_32 | B33: ='HSE Checklist'!B42 -> Plano de gestao de tráfego atualizado | C33: 2 | D33: =IF('HSE Checklist'!F42<>"",'HSE Checklist'!F42,"") | E33: =1/COUNTA($A$2:$A$110) -> 0.0091743119 | F33: =IF(D33="X",0,1/(COUNTA($A$2:$A$110)-COUNTIF($D$2:$D$110,"X"))) -> 0.0095238095 | G33: =IF(D33="X",F33,IF('HSE Checklist'!D42="X",F33,-F33)) -> 0.0095238095
A34: 2_1 | B34: ='HSE Checklist'!B44 -> Placa de obra (instalação e estado de conservação) | C34: 1 | D34: =IF('HSE Checklist'!F44<>"",'HSE Checklist'!F44,"") | E34: =1/COUNTA($A$2:$A$110) -> 0.0091743119 | F34: =IF(D34="X",0,1/(COUNTA($A$2:$A$110)-COUNTIF($D$2:$D$110,"X"))) -> 0.0095238095 | G34: =IF(D34="X",F34,IF('HSE Checklist'!D44="X",F34,-F34)) -> 0.0095238095
A35: 2_2 | B35: ='HSE Checklist'!B45 -> Lonas VAMED (instalação e estado de conservação) | C35: 1 | D35: =IF('HSE Checklist'!F45<>"",'HSE Checklist'!F45,"") | E35: =1/COUNTA($A$2:$A$110) -> 0.0091743119 | F35: =IF(D35="X",0,1/(COUNTA($A$2:$A$110)-COUNTIF($D$2:$D$110,"X"))) -> 0.0095238095 | G35: =IF(D35="X",F35,IF('HSE Checklist'!D45="X",F35,-F35)) -> 0.0095238095
A36: 2_3 | B36: ='HSE Checklist'!B46 -> PVC de tapume (20m em 20m – instalação e estado de conservação) | C36: 1 | D36: =IF('HSE Checklist'!F46<>"",'HSE Checklist'!F46,"") | E36: =1/COUNTA($A$2:$A$110) -> 0.0091743119 | F36: =IF(D36="X",0,1/(COUNTA($A$2:$A$110)-COUNTIF($D$2:$D$110,"X"))) -> 0.0095238095 | G36: =IF(D36="X",F36,IF('HSE Checklist'!D46="X",F36,-F36)) -> 0.0095238095
A37: 2_4 | B37: ='HSE Checklist'!B47 -> Mastros + bandeiras (instalação e estado de conservação) | C37: 1 | D37: =IF('HSE Checklist'!F47<>"",'HSE Checklist'!F47,"") | E37: =1/COUNTA($A$2:$A$110) -> 0.0091743119 | F37: =IF(D37="X",0,1/(COUNTA($A$2:$A$110)-COUNTIF($D$2:$D$110,"X"))) -> 0.0095238095 | G37: =IF(D37="X",F37,IF('HSE Checklist'!D47="X",F37,-F37)) -> 0.0095238095
A38: 2_5 | B38: ='HSE Checklist'!B48 -> Sinalização de Entrada de Obra (instalação e estado de conservação) | C38: 1 | D38: =IF('HSE Checklist'!F48<>"",'HSE Checklist'!F48,"") | E38: =1/COUNTA($A$2:$A$110) -> 0.0091743119 | F38: =IF(D38="X",0,1/(COUNTA($A$2:$A$110)-COUNTIF($D$2:$D$110,"X"))) -> 0.0095238095 | G38: =IF(D38="X",F38,IF('HSE Checklist'!D48="X",F38,-F38)) -> 0.0095238095
A39: 3_1 | B39: ='HSE Checklist'!B50 -> Controlo de acessos implementado | C39: 2 | D39: =IF('HSE Checklist'!F50<>"",'HSE Checklist'!F50,"") | E39: =1/COUNTA($A$2:$A$110) -> 0.0091743119 | F39: =IF(D39="X",0,1/(COUNTA($A$2:$A$110)-COUNTIF($D$2:$D$110,"X"))) -> 0.0095238095 | G39: =IF(D39="X",F39,IF('HSE Checklist'!D50="X",F39,-F39)) -> 0.0095238095
A40: 3_2 | B40: ='HSE Checklist'!B51 -> Sinal de Proibição de Circulação a mais de 20 Km/h | C40: 1 | D40: =IF('HSE Checklist'!F51<>"",'HSE Checklist'!F51,"") | E40: =1/COUNTA($A$2:$A$110) -> 0.0091743119 | F40: =IF(D40="X",0,1/(COUNTA($A$2:$A$110)-COUNTIF($D$2:$D$110,"X"))) -> 0.0095238095 | G40: =IF(D40="X",F40,IF('HSE Checklist'!D51="X",F40,-F40)) -> 0.0095238095
A41: 3_3 | B41: ='HSE Checklist'!B52 -> Estacionamento identificado e sinalizado | C41: 2 | D41: =IF('HSE Checklist'!F52<>"",'HSE Checklist'!F52,"") | E41: =1/COUNTA($A$2:$A$110) -> 0.0091743119 | F41: =IF(D41="X",0,1/(COUNTA($A$2:$A$110)-COUNTIF($D$2:$D$110,"X"))) -> 0.0095238095 | G41: =IF(D41="X",F41,IF('HSE Checklist'!D52="X",F41,-F41)) -> 0.0095238095
A42: 3_4 | B42: ='HSE Checklist'!B53 -> Limpeza do capim pelo interior da obra | C42: 2 | D42: =IF('HSE Checklist'!F53<>"",'HSE Checklist'!F53,"") | E42: =1/COUNTA($A$2:$A$110) -> 0.0091743119 | F42: =IF(D42="X",0,1/(COUNTA($A$2:$A$110)-COUNTIF($D$2:$D$110,"X"))) -> 0.0095238095 | G42: =IF(D42="X",F42,IF('HSE Checklist'!D53="X",F42,-F42)) -> 0.0095238095
A43: 3_5 | B43: ='HSE Checklist'!B54 -> Limpeza do capim pelo exterior da obra | C43: 2 | D43: =IF('HSE Checklist'!F54<>"",'HSE Checklist'!F54,"") | E43: =1/COUNTA($A$2:$A$110) -> 0.0091743119 | F43: =IF(D43="X",0,1/(COUNTA($A$2:$A$110)-COUNTIF($D$2:$D$110,"X"))) -> 0.0095238095 | G43: =IF(D43="X",F43,IF('HSE Checklist'!D54="X",F43,-F43)) -> 0.0095238095
A44: 3_6 | B44: ='HSE Checklist'!B55 -> Plano de controlo de pragas aprovado e implementado | C44: 3 | D44: =IF('HSE Checklist'!F55<>"",'HSE Checklist'!F55,"") | E44: =1/COUNTA($A$2:$A$110) -> 0.0091743119 | F44: =IF(D44="X",0,1/(COUNTA($A$2:$A$110)-COUNTIF($D$2:$D$110,"X"))) -> 0.0095238095 | G44: =IF(D44="X",F44,IF('HSE Checklist'!D55="X",F44,-F44)) -> 0.0095238095
A45: 3_7 | B45: ='HSE Checklist'!B56 -> Limpeza dos escritórios com respectivo registo | C45: 1 | D45: =IF('HSE Checklist'!F56<>"",'HSE Checklist'!F56,"") | E45: =1/COUNTA($A$2:$A$110) -> 0.0091743119 | F45: =IF(D45="X",0,1/(COUNTA($A$2:$A$110)-COUNTIF($D$2:$D$110,"X"))) -> 0.0095238095 | G45: =IF(D45="X",F45,IF('HSE Checklist'!D56="X",F45,-F45)) -> 0.0095238095
A46: 3_8 | B46: ='HSE Checklist'!B57 -> Pára-raios | C46: 3 | D46: =IF('HSE Checklist'!F57<>"",'HSE Checklist'!F57,"") | E46: =1/COUNTA($A$2:$A$110) -> 0.0091743119 | F46: =IF(D46="X",0,1/(COUNTA($A$2:$A$110)-COUNTIF($D$2:$D$110,"X"))) -> 0.0095238095 | G46: =IF(D46="X",F46,IF('HSE Checklist'!D57="X",F46,-F46)) -> 0.0095238095
A47: 3_9 | B47: ='HSE Checklist'!B58 -> Vitrina de informação de Segurança | C47: 1 | D47: =IF('HSE Checklist'!F58<>"",'HSE Checklist'!F58,"") | E47: =1/COUNTA($A$2:$A$110) -> 0.0091743119 | F47: =IF(D47="X",0,1/(COUNTA($A$2:$A$110)-COUNTIF($D$2:$D$110,"X"))) -> 0.0095238095 | G47: =IF(D47="X",F47,IF('HSE Checklist'!D58="X",F47,-F47)) -> 0.0095238095
A48: 3_10 | B48: ='HSE Checklist'!B59 -> Identificação dos diferentes espaços de estaleiro (escritórios, ferramentarias, armazéns e estaleiros temporários) | C48: 1 | D48: =IF('HSE Checklist'!F59<>"",'HSE Checklist'!F59,"") | E48: =1/COUNTA($A$2:$A$110) -> 0.0091743119 | F48: =IF(D48="X",0,1/(COUNTA($A$2:$A$110)-COUNTIF($D$2:$D$110,"X"))) -> 0.0095238095 | G48: =IF(D48="X",F48,IF('HSE Checklist'!D59="X",F48,-F48)) -> 0.0095238095
A49: 3_11 | B49: ='HSE Checklist'!B60 -> Análises à potabilidade da água (2 em 2 meses) | C49: 2 | D49: =IF('HSE Checklist'!F60<>"",'HSE Checklist'!F60,"") | E49: =1/COUNTA($A$2:$A$110) -> 0.0091743119 | F49: =IF(D49="X",0,1/(COUNTA($A$2:$A$110)-COUNTIF($D$2:$D$110,"X"))) -> 0.0095238095 | G49: =IF(D49="X",F49,IF('HSE Checklist'!D60="X",F49,-F49)) -> 0.0095238095
A50: 3_12 | B50: ='HSE Checklist'!B61 -> Manutenção periódica do sistema de filtragem da água | C50: 1 | D50: =IF('HSE Checklist'!F61<>"",'HSE Checklist'!F61,"") | E50: =1/COUNTA($A$2:$A$110) -> 0.0091743119 | F50: =IF(D50="X",0,1/(COUNTA($A$2:$A$110)-COUNTIF($D$2:$D$110,"X"))) -> 0.0095238095 | G50: =IF(D50="X",F50,IF('HSE Checklist'!D61="X",F50,-F50)) -> 0.0095238095
... A62: 3_24 | B62: ='HSE Checklist'!B73 -> Vedação e cobertura do depósito de combustível e geradores | C62: 3 | D62: =IF('HSE Checklist'!F73<>"",'HSE Checklist'!F73,"") | E62: =1/COUNTA($A$2:$A$110) -> 0.0091743119 | F62: =IF(D62="X",0,1/(COUNTA($A$2:$A$110)-COUNTIF($D$2:$D$110,"X"))) -> 0.0095238095 | G62: =IF(D62="X",F62,IF('HSE Checklist'!D73="X",F62,-F62)) -> 0.0095238095
A63: 4_1 | B63: ='HSE Checklist'!B75 -> Criação das Equipas de Emergência com atribuição de autocolante respectivo (Brigadista, Socorrista e Equipas de Evacuação) | C63: 2 | D63: =IF('HSE Checklist'!F75<>"",'HSE Checklist'!F75,"") | E63: =1/COUNTA($A$2:$A$110) -> 0.0091743119 | F63: =IF(D63="X",0,1/(COUNTA($A$2:$A$110)-COUNTIF($D$2:$D$110,"X"))) -> 0.0095238095 | G63: =IF(D63="X",F63,IF('HSE Checklist'!D75="X",F63,-F63)) -> 0.0095238095
A64: 4_2 | B64: ='HSE Checklist'!B76 -> Instalação de sistema de alarme eficaz | C64: 2 | D64: =IF('HSE Checklist'!F76<>"",'HSE Checklist'!F76,"") | E64: =1/COUNTA($A$2:$A$110) -> 0.0091743119 | F64: =IF(D64="X",0,1/(COUNTA($A$2:$A$110)-COUNTIF($D$2:$D$110,"X"))) -> 0.0095238095 | G64: =IF(D64="X",F64,IF('HSE Checklist'!D76="X",F64,-F64)) -> 0.0095238095
A65: 4_3 | B65: ='HSE Checklist'!B77 -> Sinal de Ponto de Encontro | C65: 1 | D65: =IF('HSE Checklist'!F77<>"",'HSE Checklist'!F77,"") | E65: =1/COUNTA($A$2:$A$110) -> 0.0091743119 | F65: =IF(D65="X",0,1/(COUNTA($A$2:$A$110)-COUNTIF($D$2:$D$110,"X"))) -> 0.0095238095 | G65: =IF(D65="X",F65,IF('HSE Checklist'!D77="X",F65,-F65)) -> 0.0095238095
A66: 4_4 | B66: ='HSE Checklist'!B78 -> Realização de simulacro | C66: 3 | D66: =IF('HSE Checklist'!F78<>"",'HSE Checklist'!F78,"") | E66: =1/COUNTA($A$2:$A$110) -> 0.0091743119 | F66: =IF(D66="X",0,1/(COUNTA($A$2:$A$110)-COUNTIF($D$2:$D$110,"X"))) -> 0.0095238095 | G66: =IF(D66="X",F66,IF('HSE Checklist'!D78="X",F66,-F66)) -> 0.0095238095
A67: 4_8 | B67: ='HSE Checklist'!B79 -> Caixa de primeiros socorros – existência | C67: 1 | D67: =IF('HSE Checklist'!F79<>"",'HSE Checklist'!F79,"") | E67: =1/COUNTA($A$2:$A$110) -> 0.0091743119 | F67: =IF(D67="X",0,1/(COUNTA($A$2:$A$110)-COUNTIF($D$2:$D$110,"X"))) -> 0.0095238095 | G67: =IF(D67="X",F67,IF('HSE Checklist'!D79="X",F67,-F67)) -> 0.0095238095
A68: 4_9 | B68: ='HSE Checklist'!B80 -> Extintores – existência | C68: 1 | D68: =IF('HSE Checklist'!F80<>"",'HSE Checklist'!F80,"") | E68: =1/COUNTA($A$2:$A$110) -> 0.0091743119 | F68: =IF(D68="X",0,1/(COUNTA($A$2:$A$110)-COUNTIF($D$2:$D$110,"X"))) -> 0.0095238095 | G68: =IF(D68="X",F68,IF('HSE Checklist'!D80="X",F68,-F68)) -> -0.0095238095
A69: 4_10 | B69: ='HSE Checklist'!B81 -> Existência de sinalização de emergência | C69: 1 | D69: =IF('HSE Checklist'!F81<>"",'HSE Checklist'!F81,"") | E69: =1/COUNTA($A$2:$A$110) -> 0.0091743119 | F69: =IF(D69="X",0,1/(COUNTA($A$2:$A$110)-COUNTIF($D$2:$D$110,"X"))) -> 0.0095238095 | G69: =IF(D69="X",F69,IF('HSE Checklist'!D81="X",F69,-F69)) -> 0.0095238095
A70: 4_11 | B70: ='HSE Checklist'!B82 -> Existência de maca em obra | C70: 2 | D70: =IF('HSE Checklist'!F82<>"",'HSE Checklist'!F82,"") | E70: =1/COUNTA($A$2:$A$110) -> 0.0091743119 | F70: =IF(D70="X",0,1/(COUNTA($A$2:$A$110)-COUNTIF($D$2:$D$110,"X"))) -> 0.0095238095 | G70: =IF(D70="X",F70,IF('HSE Checklist'!D82="X",F70,-F70)) -> 0.0095238095
...

Sheet Pre_database
A1: Date | B1: Parent ID | C1: Parent Item | D1: ID | E1: Item | F1: Evaluation | G1: Total Evaluation (month)
A2: =Calc!$G$1 -> 45017 | B2: ='HSE Checklist'!$A$10 -> 1 | C2: ='HSE Checklist'!B10 -> Documentação / Procedimentos de obra | D2: 1_1 | E2: ='HSE Checklist'!B11 -> Manual HSE VAMED actualizado | F2: =VLOOKUP(D2,Calc!A2:G108,7,FALSE) -> 0.0095238095 | G2: =Calc!$G$112 -> EXCELENTE
A3: =Calc!$G$1 -> 45017 | B3: ='HSE Checklist'!$A$10 -> 1 | C3: =$C$2 -> Documentação / Procedimentos de obra | D3: 1_2 | E3: ='HSE Checklist'!B12 -> Licença de Obra (afixada) | F3: =VLOOKUP(D3,Calc!A3:G109,7,FALSE) -> 0.0095238095 | G3: =Calc!$G$112 -> EXCELENTE
A4: =Calc!$G$1 -> 45017 | B4: ='HSE Checklist'!$A$10 -> 1 | C4: =$C$2 -> Documentação / Procedimentos de obra | D4: 1_3 | E4: ='HSE Checklist'!B13 -> Plano de Segurança e Saúde aprovado | F4: =VLOOKUP(D4,Calc!A4:G110,7,FALSE) -> 0.0095238095 | G4: =Calc!$G$112 -> EXCELENTE
A5: =Calc!$G$1 -> 45017 | B5: ='HSE Checklist'!$A$10 -> 1 | C5: =$C$2 -> Documentação / Procedimentos de obra | D5: 1_4 | E5: ='HSE Checklist'!B14 -> Plano de Gestão Ambiental aprovado | F5: =VLOOKUP(D5,Calc!A5:G111,7,FALSE) -> 0.0095238095 | G5: =Calc!$G$112 -> EXCELENTE
A6: =Calc!$G$1 -> 45017 | B6: ='HSE Checklist'!$A$10 -> 1 | C6: =$C$2 -> Documentação / Procedimentos de obra | D6: 1_5 | E6: ='HSE Checklist'!B15 -> Plano de Gestão de Resíduos aprovado pela ANR | F6: =VLOOKUP(D6,Calc!A6:G112,7,FALSE) -> 0.0095238095 | G6: =Calc!$G$112 -> EXCELENTE
A7: =Calc!$G$1 -> 45017 | B7: ='HSE Checklist'!$A$10 -> 1 | C7: =$C$2 -> Documentação / Procedimentos de obra | D7: 1_6 | E7: ='HSE Checklist'!B16 -> Licença dos geradores | F7: =VLOOKUP(D7,Calc!A7:G114,7,FALSE) -> 0.0095238095 | G7: =Calc!$G$112 -> EXCELENTE
A8: =Calc!$G$1 -> 45017 | B8: ='HSE Checklist'!$A$10 -> 1 | C8: =$C$2 -> Documentação / Procedimentos de obra | D8: 1_7 | E8: ='HSE Checklist'!B17 -> Certificado dos Bombeiros | F8: =VLOOKUP(D8,Calc!A8:G115,7,FALSE) -> 0.0095238095 | G8: =Calc!$G$112 -> EXCELENTE
A9: =Calc!$G$1 -> 45017 | B9: ='HSE Checklist'!$A$10 -> 1 | C9: =$C$2 -> Documentação / Procedimentos de obra | D9: 1_8 | E9: ='HSE Checklist'!B18 -> Procedimentos de Segurança submetidos e aprovados para as actividades em curso | F9: =VLOOKUP(D9,Calc!A9:G116,7,FALSE) -> 0.0095238095 | G9: =Calc!$G$112 -> EXCELENTE
A10: =Calc!$G$1 -> 45017 | B10: ='HSE Checklist'!$A$10 -> 1 | C10: =$C$2 -> Documentação / Procedimentos de obra | D10: 1_9 | E10: ='HSE Checklist'!B19 -> Documentação dos trabalhadores (Documento de identificação, atestado médico, Entrega EPI, Certificado Aptidão) | F10: =VLOOKUP(D10,Calc!A10:G117,7,FALSE) -> 0.0095238095 | G10: =Calc!$G$112 -> EXCELENTE
A11: =Calc!$G$1 -> 45017 | B11: ='HSE Checklist'!$A$10 -> 1 | C11: =$C$2 -> Documentação / Procedimentos de obra | D11: 1_10 | E11: ='HSE Checklist'!B20 -> Documentação das empresas (Alvará, Seguro AT, Contribuinte e Seg. Social) | F11: =VLOOKUP(D11,Calc!A11:G118,7,FALSE) -> 0.0095238095 | G11: =Calc!$G$112 -> EXCELENTE
A12: =Calc!$G$1 -> 45017 | B12: ='HSE Checklist'!$A$10 -> 1 | C12: =$C$2 -> Documentação / Procedimentos de obra | D12: 1_11 | E12: ='HSE Checklist'!B21 -> Documentação dos equipamentos | F12: =VLOOKUP(D12,Calc!A12:G119,7,FALSE) -> 0.0095238095 | G12: =Calc!$G$112 -> EXCELENTE
A13: =Calc!$G$1 -> 45017 | B13: ='HSE Checklist'!$A$10 -> 1 | C13: =$C$2 -> Documentação / Procedimentos de obra | D13: 1_12 | E13: ='HSE Checklist'!B22 -> Indução com atribuição de autocolante | F13: =VLOOKUP(D13,Calc!A13:G120,7,FALSE) -> 0.0095238095 | G13: =Calc!$G$112 -> EXCELENTE
A14: =Calc!$G$1 -> 45017 | B14: ='HSE Checklist'!$A$10 -> 1 | C14: =$C$2 -> Documentação / Procedimentos de obra | D14: 1_13 | E14: ='HSE Checklist'!B23 -> Reunião semanal HSE implementada | F14: =VLOOKUP(D14,Calc!A14:G121,7,FALSE) -> 0.0095238095 | G14: =Calc!$G$112 -> EXCELENTE
A15: =Calc!$G$1 -> 45017 | B15: ='HSE Checklist'!$A$10 -> 1 | C15: =$C$2 -> Documentação / Procedimentos de obra | D15: 1_14 | E15: ='HSE Checklist'!B24 -> Relatório mensal implementado | F15: =VLOOKUP(D15,Calc!A15:G122,7,FALSE) -> 0.0095238095 | G15: =Calc!$G$112 -> EXCELENTE
A16: =Calc!$G$1 -> 45017 | B16: ='HSE Checklist'!$A$10 -> 1 | C16: =$C$2 -> Documentação / Procedimentos de obra | D16: 1_15 | E16: ='HSE Checklist'!B25 -> Quadro de sinistralidade | F16: =VLOOKUP(D16,Calc!A16:G123,7,FALSE) -> 0.0095238095 | G16: =Calc!$G$112 -> EXCELENTE
A17: =Calc!$G$1 -> 45017 | B17: ='HSE Checklist'!$A$10 -> 1 | C17: =$C$2 -> Documentação / Procedimentos de obra | D17: 1_16 | E17: ='HSE Checklist'!B26 -> Investigação de acidentes | F17: =VLOOKUP(D17,Calc!A17:G124,7,FALSE) -> 0 | G17: =Calc!$G$112 -> EXCELENTE
A18: =Calc!$G$1 -> 45017 | B18: ='HSE Checklist'!$A$10 -> 1 | C18: =$C$2 -> Documentação / Procedimentos de obra | D18: 1_17 | E18: ='HSE Checklist'!B27 -> Relatório trimestral (INGA) | F18: =VLOOKUP(D18,Calc!A18:G125,7,FALSE) -> 0.0095238095 | G18: =Calc!$G$112 -> EXCELENTE
... A33: =Calc!$G$1 -> 45017 | B33: ='HSE Checklist'!$A$10 -> 1 | C33: =$C$2 -> Documentação / Procedimentos de obra | D33: 1_32 | E33: ='HSE Checklist'!B42 -> Plano de gestao de tráfego atualizado | F33: =VLOOKUP(D33,Calc!A33:G140,7,FALSE) -> 0.0095238095 | G33: =Calc!$G$112 -> EXCELENTE
A34: =Calc!$G$1 -> 45017 | B34: ='HSE Checklist'!$A$43 -> 2 | C34: ='HSE Checklist'!B43 -> Plano de imagem | D34: 2_1 | E34: ='HSE Checklist'!B44 -> Placa de obra (instalação e estado de conservação) | F34: =VLOOKUP(D34,Calc!A34:G141,7,FALSE) -> 0.0095238095 | G34: =Calc!$G$112 -> EXCELENTE
A35: =Calc!$G$1 -> 45017 | B35: ='HSE Checklist'!$A$43 -> 2 | C35: =$C$34 -> Plano de imagem | D35: 2_2 | E35: ='HSE Checklist'!B45 -> Lonas VAMED (instalação e estado de conservação) | F35: =VLOOKUP(D35,Calc!A35:G142,7,FALSE) -> 0.0095238095 | G35: =Calc!$G$112 -> EXCELENTE
A36: =Calc!$G$1 -> 45017 | B36: ='HSE Checklist'!$A$43 -> 2 | C36: =$C$34 -> Plano de imagem | D36: 2_3 | E36: ='HSE Checklist'!B46 -> PVC de tapume (20m em 20m – instalação e estado de conservação) | F36: =VLOOKUP(D36,Calc!A36:G143,7,FALSE) -> 0.0095238095 | G36: =Calc!$G$112 -> EXCELENTE
A37: =Calc!$G$1 -> 45017 | B37: ='HSE Checklist'!$A$43 -> 2 | C37: =$C$34 -> Plano de imagem | D37: 2_4 | E37: ='HSE Checklist'!B47 -> Mastros + bandeiras (instalação e estado de conservação) | F37: =VLOOKUP(D37,Calc!A37:G144,7,FALSE) -> 0.0095238095 | G37: =Calc!$G$112 -> EXCELENTE
A38: =Calc!$G$1 -> 45017 | B38: ='HSE Checklist'!$A$43 -> 2 | C38: =$C$34 -> Plano de imagem | D38: 2_5 | E38: ='HSE Checklist'!B48 -> Sinalização de Entrada de Obra (instalação e estado de conservação) | F38: =VLOOKUP(D38,Calc!A38:G145,7,FALSE) -> 0.0095238095 | G38: =Calc!$G$112 -> EXCELENTE
A39: =Calc!$G$1 -> 45017 | B39: 3 | C39: ='HSE Checklist'!B49 -> Estaleiro (Geral) | D39: 3_1 | E39: ='HSE Checklist'!B50 -> Controlo de acessos implementado | F39: =VLOOKUP(D39,Calc!A39:G146,7,FALSE) -> 0.0095238095 | G39: =Calc!$G$112 -> EXCELENTE
A40: =Calc!$G$1 -> 45017 | B40: 3 | C40: =$C$39 -> Estaleiro (Geral) | D40: 3_2 | E40: ='HSE Checklist'!B51 -> Sinal de Proibição de Circulação a mais de 20 Km/h | F40: =VLOOKUP(D40,Calc!A40:G147,7,FALSE) -> 0.0095238095 | G40: =Calc!$G$112 -> EXCELENTE
A41: =Calc!$G$1 -> 45017 | B41: 3 | C41: =$C$39 -> Estaleiro (Geral) | D41: 3_3 | E41: ='HSE Checklist'!B52 -> Estacionamento identificado e sinalizado | F41: =VLOOKUP(D41,Calc!A41:G148,7,FALSE) -> 0.0095238095 | G41: =Calc!$G$112 -> EXCELENTE
A42: =Calc!$G$1 -> 45017 | B42: 3 | C42: =$C$39 -> Estaleiro (Geral) | D42: 3_4 | E42: ='HSE Checklist'!B53 -> Limpeza do capim pelo interior da obra | F42: =VLOOKUP(D42,Calc!A42:G149,7,FALSE) -> 0.0095238095 | G42: =Calc!$G$112 -> EXCELENTE
A43: =Calc!$G$1 -> 45017 | B43: 3 | C43: =$C$39 -> Estaleiro (Geral) | D43: 3_5 | E43: ='HSE Checklist'!B54 -> Limpeza do capim pelo exterior da obra | F43: =VLOOKUP(D43,Calc!A43:G150,7,FALSE) -> 0.0095238095 | G43: =Calc!$G$112 -> EXCELENTE
A44: =Calc!$G$1 -> 45017 | B44: 3 | C44: =$C$39 -> Estaleiro (Geral) | D44: 3_6 | E44: ='HSE Checklist'!B55 -> Plano de controlo de pragas aprovado e implementado | F44: =VLOOKUP(D44,Calc!A44:G151,7,FALSE) -> 0.0095238095 | G44: =Calc!$G$112 -> EXCELENTE
A45: =Calc!$G$1 -> 45017 | B45: 3 | C45: =$C$39 -> Estaleiro (Geral) | D45: 3_7 | E45: ='HSE Checklist'!B56 -> Limpeza dos escritórios com respectivo registo | F45: =VLOOKUP(D45,Calc!A45:G152,7,FALSE) -> 0.0095238095 | G45: =Calc!$G$112 -> EXCELENTE
A46: =Calc!$G$1 -> 45017 | B46: 3 | C46: =$C$39 -> Estaleiro (Geral) | D46: 3_8 | E46: ='HSE Checklist'!B57 -> Pára-raios | F46: =VLOOKUP(D46,Calc!A46:G153,7,FALSE) -> 0.0095238095 | G46: =Calc!$G$112 -> EXCELENTE
A47: =Calc!$G$1 -> 45017 | B47: 3 | C47: =$C$39 -> Estaleiro (Geral) | D47: 3_9 | E47: ='HSE Checklist'!B58 -> Vitrina de informação de Segurança | F47: =VLOOKUP(D47,Calc!A47:G154,7,FALSE) -> 0.0095238095 | G47: =Calc!$G$112 -> EXCELENTE
A48: =Calc!$G$1 -> 45017 | B48: 3 | C48: =$C$39 -> Estaleiro (Geral) | D48: 3_10 | E48: ='HSE Checklist'!B59 -> Identificação dos diferentes espaços de estaleiro (escritórios, ferramentarias, armazéns e estaleiros temporários) | F48: =VLOOKUP(D48,Calc!A48:G155,7,FALSE) -> 0.0095238095 | G48: =Calc!$G$112 -> EXCELENTE
A49: =Calc!$G$1 -> 45017 | B49: 3 | C49: =$C$39 -> Estaleiro (Geral) | D49: 3_11 | E49: ='HSE Checklist'!B60 -> Análises à potabilidade da água (2 em 2 meses) | F49: =VLOOKUP(D49,Calc!A49:G156,7,FALSE) -> 0.0095238095 | G49: =Calc!$G$112 -> EXCELENTE
A50: =Calc!$G$1 -> 45017 | B50: 3 | C50: =$C$39 -> Estaleiro (Geral) | D50: 3_12 | E50: ='HSE Checklist'!B61 -> Manutenção periódica do sistema de filtragem da água | F50: =VLOOKUP(D50,Calc!A50:G157,7,FALSE) -> 0.0095238095 | G50: =Calc!$G$112 -> EXCELENTE
A51: =Calc!$G$1 -> 45017 | B51: 3 | C51: =$C$39 -> Estaleiro (Geral) | D51: 3_13 | E51: ='HSE Checklist'!B62 -> Sinalização da água potável | F51: =VLOOKUP(D51,Calc!A51:G158,7,FALSE) -> 0.0095238095 | G51: =Calc!$G$112 -> EXCELENTE
... A62: =Calc!$G$1 -> 45017 | B62: 3 | C62: =$C$39 -> Estaleiro (Geral) | D62: 3_24 | E62: ='HSE Checklist'!B73 -> Vedação e cobertura do depósito de combustível e geradores | F62: =VLOOKUP(D62,Calc!A62:G169,7,FALSE) -> 0.0095238095 | G62: =Calc!$G$112 -> EXCELENTE
A63: =Calc!$G$1 -> 45017 | B63: 4 | C63: ='HSE Checklist'!B74 -> Emergência | D63: 4_1 | E63: ='HSE Checklist'!B75 -> Criação das Equipas de Emergência com atribuição de autocolante respectivo (Brigadista, Socorrista e Equipas de Evacuação) | F63: =VLOOKUP(D63,Calc!A63:G170,7,FALSE) -> 0.0095238095 | G63: =Calc!$G$112 -> EXCELENTE
A64: =Calc!$G$1 -> 45017 | B64: 4 | C64: =$C$63 -> Emergência | D64: 4_2 | E64: ='HSE Checklist'!B76 -> Instalação de sistema de alarme eficaz | F64: =VLOOKUP(D64,Calc!A64:G171,7,FALSE) -> 0.0095238095 | G64: =Calc!$G$112 -> EXCELENTE
...

Sheet Database
A1: Date | B1: Parent ID | C1: Parent Item | D1: ID | E1: Item | F1: Evaluation | G1: Total Evaluation (month)
